Workbook

Sheet Premissas
A1: Premissas (mude aqui; o resto recalcula)
A2: Preços coletados em 2026-09-17. Linhas marcadas "estimativa" são chute meu com base no uso esperado: ajuste quando tiver dado real.
A4: Premissa | B4: Valor | C4: Unidade | D4: De onde veio / observação
A6: Geral
A7: Câmbio (R$ por US$) | B7: 5.5 | C7: R$/US$ | D7: Estimativa: atualize pelo dia.
A8: Semanas por mês | B8: 4.33 | C8: semanas | D8: Média do ano.
A10: OpenAI (modelo gpt-5.4-mini, o que o backend usa)
A11: Preço por 1 milhão de tokens de ENTRADA | B11: 0.75 | C11: US$ | D11: developers.openai.com/api/docs/pricing (17/09/2026).
A12: Preço por 1 milhão de tokens de SAÍDA | B12: 4.5 | C12: US$ | D12: Idem.
A13: Chat da Lu: mensagens por paciente por mês | B13: 20 | C13: msgs | D13: Estimativa. Teto atual no backend: 60/dia e 600/mês por conta (limites.js).
A14: Chat da Lu: tokens de entrada por mensagem | B14: 3000 | C14: tokens | D14: Estimativa: prompt do sistema + contexto (perfil, plano, 40 receitas candidatas) + histórico.
A15: Chat da Lu: tokens de saída por mensagem | B15: 250 | C15: tokens | D15: Estimativa (resposta curta em JSON).
A16: Foto do prato por IA: análises por paciente por mês | B16: 30 | C16: fotos | D16: Estimativa: 1/dia. Teto atual: 30/dia e 400/mês.
A17: Foto: tokens de entrada por análise | B17: 1500 | C17: tokens | D17: Estimativa: imagem (~1.000) + prompt.
A18: Foto: tokens de saída por análise | B18: 300 | C18: tokens | D18: Estimativa (JSON com itens e macros).
A19: Resumo do dia / insight por IA: por paciente por mês | B19: 0 | C19: chamadas | D19: Só existe no app de celular, que ninguém vai usar. Deixe 0; se a web ganhar isso, use 30.
A20: Resumo do dia: tokens de entrada | B20: 2000 | C20: tokens | D20: Estimativa.
A21: Resumo do dia: tokens de saída | B21: 300 | C21: tokens | D21: Estimativa.
A22: Síntese do dashboard: chamadas por dia (custo global, não por paciente) | B22: 1 | C22: chamadas | D22: 1x/dia com cache (dashboard.js).
... A24: Síntese: tokens de saída por chamada | B24: 1000 | C24: tokens | D24: Estimativa.
A26: E-mail transacional
A27: E-mails por paciente por mês | B27: 7 | C27: e-mails | D27: Estimativa: 4 códigos de login + 1 "plano pronto" + 2 recados.
A28: Provedor: plano até 50 mil e-mails/mês | B28: 20 | C28: US$/mês | D28: Resend Pro (referência de mercado; Brevo/Postmark parecidos). Hoje o backend usa SMTP da caixa Titan, que NÃO serve pra volume: precisa trocar.
A29: Provedor: plano até 100 mil e-mails/mês | B29: 90 | C29: US$/mês | D29: Resend Scale.
A30: Acima de 100 mil: custo por e-mail adicional | B30: 0.0009 | C30: US$ | D30: Estimativa a partir das faixas maiores; confirmar no provedor escolhido.
A32: Cloudflare R2 (fotos dos pratos e PDFs)
A33: Fotos enviadas por paciente por mês | B33: 30 | C33: fotos | D33: Estimativa: 1/dia.
A34: Tamanho médio da foto | B34: 150 | C34: KB | D34: Estimativa: o app redimensiona antes de subir.
A35: Meses de fotos acumuladas (retenção) | B35: 6 | C35: meses | D35: Estimativa: hoje nada é apagado. Definir política de retenção baixa o custo.
A36: Armazenamento | B36: 0.015 | C36: US$/GB-mês | D36: developers.cloudflare.com/r2/pricing (10 GB grátis/mês).
A37: Operações classe A (upload) | B37: 4.5 | C37: US$/milhão | D37: Idem (1 milhão grátis/mês).
A38: Operações classe B (leitura) | B38: 0.36 | C38: US$/milhão | D38: Idem (10 milhões grátis/mês). Sem custo de saída de dados.
A39: Leituras por foto ao longo da vida | B39: 10 | C39: leituras | D39: Estimativa (paciente + painel da nutri).
A41: Railway (API + Postgres)
A42: vCPU | B42: 20 | C42: US$/vCPU-mês | D42: railway.com/pricing (17/09/2026).
A43: Memória | B43: 10 | C43: US$/GB-mês | D43: Idem.
A44: Volume (disco do Postgres) | B44: 0.15 | C44: US$/GB-mês | D44: Idem.
A45: Saída de dados | B45: 0.05 | C45: US$/GB | D45: Idem.
A46: Plano Pro (por assento) | B46: 20 | C46: US$/mês | D46: Idem. Hoje está no Hobby (US$ 5, inclui US$ 5 de uso). Pro traz mais limite de recursos e suporte.
A48: WhatsApp (bot ainda não existe; deixe 0 até existir)
...

Sheet Por paciente
A1: Custo variável por paciente por mês
A2: Só o que cresce com cada paciente. Infra e planos de e-mail estão na aba Cenários, porque vêm em degraus.
A4: Item | B4: US$/mês | C4: R$/mês | D4: Como foi calculado
A5: Chat da Lu (IA) | B5: =Premissas!$B$13*(Premissas!$B$14*Premissas!$B$11+Premissas!$B$15*Premissas!$B$12)/1000000 -> 0.0675 | C5: =B5*Premissas!$B$7 -> 0.37125 | D5: msgs × (entrada × preço + saída × preço)
A6: Foto do prato (IA) | B6: =Premissas!$B$16*(Premissas!$B$17*Premissas!$B$11+Premissas!$B$18*Premissas!$B$12)/1000000 -> 0.07425 | C6: =B6*Premissas!$B$7 -> 0.408375 | D6: análises × (entrada × preço + saída × preço)
A7: Resumo do dia (IA, só app) | B7: =Premissas!$B$19*(Premissas!$B$20*Premissas!$B$11+Premissas!$B$21*Premissas!$B$12)/1000000 -> 0 | C7: =B7*Premissas!$B$7 -> 0 | D7: idem
A8: R2: fotos guardadas | B8: =(Premissas!$B$33*Premissas!$B$34*Premissas!$B$35/1024/1024)*Premissas!$B$36 -> 0.0003862381 | C8: =B8*Premissas!$B$7 -> 0.0021243095 | D8: fotos/mês × KB × meses de retenção → GB × preço
A9: R2: uploads e leituras | B9: =Premissas!$B$33*(Premissas!$B$37+Premissas!$B$39*Premissas!$B$38)/1000000 -> 0.000243 | C9: =B9*Premissas!$B$7 -> 0.0013365 | D9: fotos × (classe A + leituras × classe B)
A10: E-mail acima do plano (só quando passa de 100 mil/mês) | B10: =Premissas!$B$27*Premissas!$B$30 -> 0.0063 | C10: =B10*Premissas!$B$7 -> 0.03465 | D10: Usado na aba Cenários só no que exceder o plano.
A11: WhatsApp (quando existir) | B11: =Premissas!$B$49*Premissas!$B$50 -> 0 | C11: =B11*Premissas!$B$7 -> 0 | D11: msgs × preço
A13: TOTAL variável por paciente (sem o e-mail extra) | B13: ='Por paciente'!$B$5+'Por paciente'!$B$6+'Por paciente'!$B$7+'Por paciente'!$B$8+'Por paciente'!$B$9+'Por paciente'!$B$11 -> 0.14237924 | C13: =B13*Premissas!$B$7 -> 0.78308581
A15: Leitura:
A16: A IA (chat + foto) é quase todo o custo variável. Os tetos por conta em limites.js são o freio: se um paciente usar o teto inteiro do chat (600/mês), ele sozinho custa 30× a média.
A17: Cache de prompt da OpenAI (o prompt do sistema e a lista de receitas se repetem) pode cortar a entrada do chat em até ~50%. Não está contado aqui.

Sheet Cenários
A1: Cenários por número de pacientes
A2: Infra e e-mail vêm em degraus (minha estimativa de tamanho por faixa). Os totais somam a aba Por paciente × N.
B4: 1.000 pacientes | C4: 5.000 pacientes | D4: 10.000 pacientes | E4: 30.000 pacientes | F4: Observação
A5: Pacientes (N) | B5: 1000 | C5: 5000 | D5: 10000 | E5: 30000 | F5: Mude aqui pra testar outro tamanho.
A7: Custo variável (aba Por paciente × N)
A8: IA + R2 + WhatsApp (US$/mês) | B8: =B$5*'Por paciente'!$B$13 -> 142.37924 | C8: =C$5*'Por paciente'!$B$13 -> 711.89619 | D8: =D$5*'Por paciente'!$B$13 -> 1423.7924 | E8: =E$5*'Por paciente'!$B$13 -> 4271.3771 | F8: Cresce linear com N.
A10: Custos em degrau
A11: E-mail transacional (US$/mês) | B11: =IF(B$5*Premissas!$B$27<=3000,0,IF(B$5*Premissas!$B$27<=50000,Premissas!$B$28,IF(B$5*Premissas!$B$27<=100000,Premissas!$B$29,Premissas!$B$29+(B$5*Premissas!$B$27-100000)*Premissas!$B$30))) -> 20 | C11: =IF(C$5*Premissas!$B$27<=3000,0,IF(C$5*Premissas!$B$27<=50000,Premissas!$B$28,IF(C$5*Premissas!$B$27<=100000,Premissas!$B$29,Premissas!$B$29+(C$5*Premissas!$B$27-100000)*Premissas!$B$30))) -> 20 | D11: =IF(D$5*Premissas!$B$27<=3000,0,IF(D$5*Premissas!$B$27<=50000,Premissas!$B$28,IF(D$5*Premissas!$B$27<=100000,Premissas!$B$29,Premissas!$B$29+(D$5*Premissas!$B$27-100000)*Premissas!$B$30))) -> 90 | E11: =IF(E$5*Premissas!$B$27<=3000,0,IF(E$5*Premissas!$B$27<=50000,Premissas!$B$28,IF(E$5*Premissas!$B$27<=100000,Premissas!$B$29,Premissas!$B$29+(E$5*Premissas!$B$27-100000)*Premissas!$B$30))) -> 189 | F11: Faixas: até 3 mil grátis, até 50 mil, até 100 mil, depois por e-mail.
A12: API: vCPU | B12: 1 | C12: 2 | D12: 2 | E12: 4 | F12: Estimativa de dimensionamento.
A13: API: GB de RAM | B13: 1 | C13: 2 | D13: 4 | E13: 8
A14: Postgres: vCPU | B14: 1 | C14: 2 | D14: 2 | E14: 4
A15: Postgres: GB de RAM | B15: 2 | C15: 4 | D15: 8 | E15: 16
A16: Postgres: GB de disco | B16: 5 | C16: 15 | D16: 30 | E16: 80 | F16: Registros de refeição, planos, mensagens.
A17: Saída de dados (GB/mês) | B17: 30 | C17: 120 | D17: 250 | E17: 700 | F17: API + fotos assinadas passam pelo R2, não por aqui.
A18: Railway total (US$/mês) | B18: =Premissas!$B$46+(B12+B14)*Premissas!$B$42+(B13+B15)*Premissas!$B$43+B16*Premissas!$B$44+B17*Premissas!$B$45 -> 92.25 | C18: =Premissas!$B$46+(C12+C14)*Premissas!$B$42+(C13+C15)*Premissas!$B$43+C16*Premissas!$B$44+C17*Premissas!$B$45 -> 168.25 | D18: =Premissas!$B$46+(D12+D14)*Premissas!$B$42+(D13+D15)*Premissas!$B$43+D16*Premissas!$B$44+D17*Premissas!$B$45 -> 237 | E18: =Premissas!$B$46+(E12+E14)*Premissas!$B$42+(E13+E15)*Premissas!$B$43+E16*Premissas!$B$44+E17*Premissas!$B$45 -> 467 | F18: Plano Pro + recursos × preço.
A19: Síntese do dashboard por IA (US$/mês) | B19: =Premissas!$B$22*30*(Premissas!$B$23*Premissas!$B$11+Premissas!$B$24*Premissas!$B$12)/1000000 -> 0.585 | C19: =Premissas!$B$22*30*(Premissas!$B$23*Premissas!$B$11+Premissas!$B$24*Premissas!$B$12)/1000000 -> 0.585 | D19: =Premissas!$B$22*30*(Premissas!$B$23*Premissas!$B$11+Premissas!$B$24*Premissas!$B$12)/1000000 -> 0.585 | E19: =Premissas!$B$22*30*(Premissas!$B$23*Premissas!$B$11+Premissas!$B$24*Premissas!$B$12)/1000000 -> 0.585 | F19: Global, não depende de N.
A20: Cloudflare Pages (site + área de membros) | B20: 0 | C20: 0 | D20: 0 | E20: 0 | F20: Plano grátis serve.
A22: TOTAL (US$/mês) | B22: =B8+B11+B18+B19+B20 -> 255.21424 | C22: =C8+C11+C18+C19+C20 -> 900.73119 | D22: =D8+D11+D18+D19+D20 -> 1751.3774 | E22: =E8+E11+E18+E19+E20 -> 4927.9621
A23: TOTAL (R$/mês) | B23: =B22*Premissas!$B$7 -> 1403.6783 | C23: =C22*Premissas!$B$7 -> 4954.0215 | D23: =D22*Premissas!$B$7 -> 9632.5756 | E23: =E22*Premissas!$B$7 -> 27103.792
A24: Custo por paciente (R$/mês) | B24: =B23/B$5 -> 1.4036783 | C24: =C23/C$5 -> 0.99080431 | D24: =D23/D$5 -> 0.96325756 | E24: =E23/E$5 -> 0.90345973 | F24: É esse número que tem que caber no ticket.
A26: Tempo da equipe
A27: Horas de nutri por mês | B27: =(B$5*Premissas!$B$53+B$5*Premissas!$B$55*Premissas!$B$54)/60 -> 200 | C27: =(C$5*Premissas!$B$53+C$5*Premissas!$B$55*Premissas!$B$54)/60 -> 1000 | D27: =(D$5*Premissas!$B$53+D$5*Premissas!$B$55*Premissas!$B$54)/60 -> 2000 | E27: =(E$5*Premissas!$B$53+E$5*Premissas!$B$55*Premissas!$B$54)/60 -> 6000 | F27: Planos + dúvidas.
A28: Nutris necessárias (tempo integral) | B28: =B27/Premissas!$B$56 -> 1.4285714 | C28: =C27/Premissas!$B$56 -> 7.1428571 | D28: =D27/Premissas!$B$56 -> 14.285714 | E28: =E27/Premissas!$B$56 -> 42.857143 | F28: Sem aprovação em lote, a Lu sozinha para em ~1.000 pacientes.
A30: Receita (se o ticket estiver preenchido)
A31: Receita líquida da Hotmart (R$/mês) | B31: =IF(Premissas!$B$59>0,B$5*(Premissas!$B$59*(1-Premissas!$B$60)-Premissas!$B$61),0) -> 0 | C31: =IF(Premissas!$B$59>0,C$5*(Premissas!$B$59*(1-Premissas!$B$60)-Premissas!$B$61),0) -> 0 | D31: =IF(Premissas!$B$59>0,D$5*(Premissas!$B$59*(1-Premissas!$B$60)-Premissas!$B$61),0) -> 0 | E31: =IF(Premissas!$B$59>0,E$5*(Premissas!$B$59*(1-Premissas!$B$60)-Premissas!$B$61),0) -> 0 | F31: N × (ticket − taxa Hotmart).
A32: Margem antes de equipe e impostos (R$/mês) | B32: =IF(Premissas!$B$59>0,B31-B23,0) -> 0 | C32: =IF(Premissas!$B$59>0,C31-C23,0) -> 0 | D32: =IF(Premissas!$B$59>0,D31-D23,0) -> 0 | E32: =IF(Premissas!$B$59>0,E31-E23,0) -> 0 | F32: Não inclui salário das nutris, impostos nem marketing.

Sheet Fontes e decisões
A1: De onde vieram os números e o que precisa decidir
A3: OpenAI | B3: https://developers.openai.com/api/docs/pricing — gpt-5.4-mini: US$ 0,75/1M entrada, US$ 4,50/1M saída (17/09/2026).
A4: Railway | B4: https://railway.com/pricing — US$ 20/vCPU-mês, US$ 10/GB RAM-mês, US$ 0,15/GB volume, US$ 0,05/GB saída; Hobby US$ 5, Pro US$ 20/assento.
A5: Cloudflare R2 | B5: https://developers.cloudflare.com/r2/pricing — US$ 0,015/GB-mês, classe A US$ 4,50/M, classe B US$ 0,36/M, saída grátis.
A6: E-mail | B6: Resend (referência): Pro US$ 20 até 50 mil/mês, Scale US$ 90 até 100 mil/mês. Confirmar no provedor escolhido.
A7: WhatsApp | B7: Tabela pública da Meta pra mensagens utilitárias no Brasil (~US$ 0,008). Confirmar com o BSP na contratação.
A8: Hotmart | B8: Taxa pública 9,9% + R$ 1 por venda. Confirmar no contrato.
A10: DECISÕES PENDENTES
A11: 1. Provedor de e-mail | B11: Hoje o backend manda pelo SMTP da caixa Titan. Caixa de e-mail tem limite de envio diário e vai bloquear no lançamento. Trocar por transacional (Resend, Brevo, Postmark) antes de abrir a venda.
A12: 2. Railway Hobby → Pro | B12: Hobby é 1 instância pequena. Antes de 1.000 pacientes, passar pra Pro e dimensionar API e Postgres.
A13: 3. Retenção de fotos | B13: Definir quantos meses de foto do prato ficam guardados. Muda o custo do R2 e é uma decisão de LGPD também.
A14: 4. Aprovação em lote | B14: Com o editor atual a Lu para em ~1.000 pacientes. Precisa de geração automática com revisão por exceção e/ou mais nutris com o papel "nutri".
A15: 5. Ticket | B15: Preencha o ticket na aba Premissas pra ver a margem por cenário.
